<mujoco model="pendulum">
  <include file="./common/visual.xml"/>
  <include file="./common/skybox.xml"/>
  <include file="./common/materials.xml"/>

  <option timestep="0.001" integrator="RK4">
    <flag contact="disable" energy="enable"/>
  </option>

  <worldbody>
    <light name="light" pos="0 0 3"/>
    <geom name="floor" size="2 2 .2" type="plane" material="grid"/>
    <camera name="fixed" pos="0 -1.5 2" xyaxes="1 0 0 0 1 1"/>
    <camera name="lookat" mode="targetbodycom" target="pole_1" pos="0 -2 1"/>
    <body name="pole_1" pos="0 0 1.2">
      <joint name="hinge_1" type="hinge" axis="0 1 0" damping="0.01"/>
      <geom name="base" material="decoration" type="cylinder" fromto="0 -0.03 0 0 0.03 0" size="0.021" mass="0"/>
      <geom name="pole_1"  material="self" type="capsule" fromto="0 0 0 0 0 0.5" size="0.02" mass="1"/>
      <body name="pole_2" pos="0 0 0.5">
        <joint name="hinge_2" type="hinge" axis="0 1 0" damping="0.01"/>
        <geom name="pole_2" material="self" type="capsule" fromto="0 0 0 0 0 0.5" size="0.02" mass="1"/>
        <geom name="mass" material="effector" type="sphere" pos="0 0 0.5" size="0.025" mass="0"/>
      </body>
    </body>
  </worldbody>

  <actuator>
    <motor name="torque_1" joint="hinge_1" gear="1" ctrlrange="-1 1" ctrllimited="true"/>
    <motor name="torque_2" joint="hinge_2" gear="1" ctrlrange="-1 1" ctrllimited="true"/>
  </actuator>
</mujoco>
